<?xml version="1.0"?>
<!-- =================================================================================== -->
<!-- |    This document was autogenerated by xacro from
/home/me/clean_ws/src/full_body_mujoco/urdf/full_body.xacro | -->
<!-- |    EDITING THIS FILE BY HAND IS NOT RECOMMENDED                                 | -->
<!-- =================================================================================== -->
<robot name="angad_full_body">
  <material name="silver">
    <color rgba="0.7 0.7 0.7 1.0" />
  </material>
  <link name="world" />

  <joint name="world_to_base" type="fixed">
    <origin xyz="0 0 0" rpy="0 0 0" />
    <parent link="world" />
    <child link="base_link" />
  </joint>

  <link name="base_link" />
  <joint name="base_link_to_pelvis" type="fixed">
    <origin rpy="0 0 0" xyz="0 0 0" />
    <parent link="base_link" />
    <child link="pelvis" />
  </joint>
  <!-- ══════════════════════════════════════════════════
       PELVIS
  ══════════════════════════════════════════════════ -->
  <link name="pelvis">
    <inertial>
      <origin rpy="0 0 0" xyz="0 0 0.109" />
      <mass value="5.565" />
      <inertia ixx="0.06430" ixy="0" ixz="0" iyy="0.07731" iyz="0" izz="0.04267" />
    </inertial>
    <visual>
      <origin rpy="0 0 0" xyz="0 0 0" />
      <geometry>
        <mesh filename="file:///home/me/clean_ws/src/XP_robot/meshes/pelvis.stl"
          scale="0.001 0.001 0.001" />
      </geometry>
      <material name="silver" />
    </visual>
    <collision>
      <origin rpy="0 0 0" xyz="0 0 0.07" />
      <geometry>
        <box size="0.145 0.14 0.24" />
      </geometry>
    </collision>
  </link>
  <!-- ══ RIGHT LEG ══ -->
  <link name="hip_pitch_r">
    <inertial>
      <origin rpy="0 0 0" xyz="-8e-05 0.00346 0.07278" />
      <mass value="1.008" />
      <inertia ixx="0.00415" ixy="0" ixz="0" iyy="0.00587" iyz="0" izz="0.00350" />
    </inertial>
    <visual>
      <origin rpy="0 0 0" xyz="0 0 0" />
      <geometry>
        <mesh filename="file:///home/me/clean_ws/src/XP_robot/meshes/hip_pitch_r.stl"
          scale="0.001 0.001 0.001" />
      </geometry>
      <material name="silver" />
    </visual>
    <collision>
      <origin rpy="0 0 0" xyz="0 0 0.06" />
      <geometry>
        <cylinder length="0.10" radius="0.035" />
      </geometry>
    </collision>
  </link>
  <joint name="hip_pitch_r" type="revolute">
    <origin rpy="-3.141593 -1.308997 -3.141593" xyz="-0.074290 0.000000 0.065550" />
    <parent link="pelvis" />
    <child link="hip_pitch_r" />
    <axis xyz="0 0 -1" />
    <limit effort="150" lower="-3.1416" upper="3.1416" velocity="5" />
    <dynamics damping="5.0" friction="0.1" />
  </joint>
  <link name="hip_roll_r">
    <inertial>
      <origin rpy="0 0 0" xyz="3.5e-05 -3e-08 0.03968" />
      <mass value="1.319" />
      <inertia ixx="0.00871" ixy="0" ixz="0" iyy="0.01037" iyz="0" izz="0.00721" />
    </inertial>
    <visual>
      <origin rpy="0 0 0" xyz="0 0 0" />
      <geometry>
        <mesh filename="file:///home/me/clean_ws/src/XP_robot/meshes/hip_roll_r.stl"
          scale="0.001 0.001 0.001" />
      </geometry>
      <material name="silver" />
    </visual>
    <collision>
      <origin rpy="0 0 0" xyz="0 0 0.04" />
      <geometry>
        <cylinder length="0.08" radius="0.035" />
      </geometry>
    </collision>
  </link>
  <link name="hip_roll_r_frame" />
  <joint name="hip_roll_r" type="revolute">
    <origin rpy="-1.832596 0.000000 -1.570796" xyz="-0.000093 -0.022500 0.077909" />
    <parent link="hip_pitch_r" />
    <child link="hip_roll_r_frame" />
    <axis xyz="1 0 0" />
    <limit effort="120" lower="-2.35" upper="0.292" velocity="5" />
    <dynamics damping="5.0" friction="0.1" />
  </joint>
  <joint name="hip_roll_r_fix" type="fixed">
    <origin rpy="0 0 0" xyz="-0.022500 0.000000 -0.143000" />
    <parent link="hip_roll_r_frame" />
    <child link="hip_roll_r" />
  </joint>
  <link name="thigh_r">
    <inertial>
      <origin rpy="0 0 0" xyz="0.01437 -0.13463 -0.04238" />
      <mass value="2.264" />
      <inertia ixx="0.04565" ixy="0" ixz="0" iyy="0.04875" iyz="0" izz="0.00823" />
    </inertial>
    <visual>
      <origin rpy="0 0 0" xyz="0 0 0" />
      <geometry>
        <mesh filename="file:///home/me/clean_ws/src/XP_robot/meshes/thigh_r.stl"
          scale="0.001 0.001 0.001" />
      </geometry>
      <material name="silver" />
    </visual>
    <collision>
      <origin rpy="0 0 0" xyz="0.01 -0.13 0.06" />
      <geometry>
        <cylinder length="0.21" radius="0.04" />
      </geometry>
    </collision>
  </link>
  <link name="thigh_yaw_r_frame" />
  <joint name="thigh_yaw_r" type="revolute">
    <origin rpy="0 0 0" xyz="0.000000 0.000000 -0.005500" />
    <parent link="hip_roll_r" />
    <child link="thigh_yaw_r_frame" />
    <axis xyz="0 0 -1" />
    <limit effort="80" lower="-3.1416" upper="3.1416" velocity="5" />
    <dynamics damping="5.0" friction="0.1" />
  </joint>
  <joint name="thigh_yaw_r_fix" type="fixed">
    <origin rpy="0 0 0" xyz="-0.011580 0.131790 -0.163040" />
    <parent link="thigh_yaw_r_frame" />
    <child link="thigh_r" />
  </joint>
  <link name="leg_shank_r">
    <inertial>
      <origin rpy="0 0 0" xyz="-0.14872 -0.00406 -0.50123" />
      <mass value="1.446" />
      <inertia ixx="0.02297" ixy="0" ixz="0" iyy="0.02434" iyz="0" izz="0.00263" />
    </inertial>
    <visual>
      <origin rpy="0 0 0" xyz="0 0 0" />
      <geometry>
        <mesh filename="file:///home/me/clean_ws/src/XP_robot/meshes/leg_shank_r.stl"
          scale="0.001 0.001 0.001" />
      </geometry>
      <material name="silver" />
    </visual>
    <collision>
      <origin rpy="0 0 0" xyz="-0.148 -0.004 -0.50" />
      <geometry>
        <cylinder length="0.32" radius="0.035" />
      </geometry>
    </collision>
  </link>
  <link name="knee_pitch_r_frame" />
  <joint name="knee_pitch_r" type="revolute">
    <origin rpy="-0.002816 0.000696 1.571419" xyz="0.011589 -0.160545 -0.086954" />
    <parent link="thigh_r" />
    <child link="knee_pitch_r_frame" />
    <axis xyz="-1 0 0" />
    <limit effort="200" lower="-1.5708" upper="0.0" velocity="5" />
    <dynamics damping="5.0" friction="0.1" />
  </joint>
  <joint name="knee_pitch_r_fix" type="fixed">
    <origin rpy="0 0 0" xyz="0.177560 0.000500 0.352910" />
    <parent link="knee_pitch_r_frame" />
    <child link="leg_shank_r" />
  </joint>
  <link name="uj_r">
    <inertial>
      <origin rpy="0 0 0" xyz="0 0 -5.22e-05" />
      <mass value="0.098" />
      <inertia ixx="1.0e-05" ixy="0" ixz="0" iyy="8.6e-06" iyz="0" izz="1.6e-05" />
    </inertial>
    <visual>
      <origin rpy="0 0 0" xyz="0 0 0" />
      <geometry>
        <mesh filename="file:///home/me/clean_ws/src/XP_robot/meshes/uj_r.stl"
          scale="0.001 0.001 0.001" />
      </geometry>
      <material name="silver" />
    </visual>
    <collision>
      <origin rpy="0 0 0" xyz="0 0 0" />
      <geometry>
        <sphere radius="0.025" />
      </geometry>
    </collision>
  </link>
  <link name="ankle_pitch_r_frame" />
  <joint name="ankle_pitch_r" type="revolute">
    <origin rpy="0.000694 0.002816 -1.571420" xyz="-0.165570 0.000677 -0.700162" />
    <parent link="leg_shank_r" />
    <child link="ankle_pitch_r_frame" />
    <axis xyz="0 1 0" />
    <limit effort="80" lower="-0.6981" upper="0.6981" velocity="5" />
    <dynamics damping="5.0" friction="0.1" />
  </joint>
  <joint name="ankle_pitch_r_fix" type="fixed">
    <origin rpy="0 0 0" xyz="0.000000 0.017000 0.000000" />
    <parent link="ankle_pitch_r_frame" />
    <child link="uj_r" />
  </joint>
  <link name="foot_r">
    <inertial>
      <origin rpy="0 0 0" xyz="-6.6e-11 0.02074 -4.8e-04" />
      <mass value="0.365" />
      <inertia ixx="8.3e-04" ixy="0" ixz="0" iyy="2.8e-04" iyz="0" izz="9.5e-04" />
    </inertial>
    <visual>
      <origin rpy="0 0 0" xyz="0 0 0" />
      <geometry>
        <mesh filename="file:///home/me/clean_ws/src/XP_robot/meshes/foot_r.stl"
          scale="0.001 0.001 0.001" />
      </geometry>
      <material name="silver" />
    </visual>
    <collision>
      <origin rpy="0 0 0" xyz="0 0.055 -0.048" />
      <geometry>
        <box size="0.06 0.14 0.02" />
      </geometry>
    </collision>
  </link>
  <link name="ankle_roll_r_frame" />
  <joint name="ankle_roll_r" type="revolute">
    <origin rpy="0.000000 0.000000 1.570796" xyz="-0.017000 0.000000 0.000000" />
    <parent link="uj_r" />
    <child link="ankle_roll_r_frame" />
    <axis xyz="0 -1 0" />
    <limit effort="60" lower="-0.3491" upper="0.3491" velocity="5" />
    <dynamics damping="5.0" friction="0.1" />
  </joint>
  <joint name="ankle_roll_r_fix" type="fixed">
    <origin rpy="0 0 0" xyz="0.000000 -0.040500 -0.030990" />
    <parent link="ankle_roll_r_frame" />
    <child link="foot_r" />
  </joint>
  <!-- ══ LEFT LEG ══ -->
  <link name="hip_pitch_l">
    <inertial>
      <origin rpy="0 0 0" xyz="-8e-05 0.00346 0.07278" />
      <mass value="1.008" />
      <inertia ixx="0.00415" ixy="0" ixz="0" iyy="0.00587" iyz="0" izz="0.00350" />
    </inertial>
    <visual>
      <origin rpy="0 0 0" xyz="0 0 0" />
      <geometry>
        <mesh filename="file:///home/me/clean_ws/src/XP_robot/meshes/hip_pitch_l.stl"
          scale="0.001 0.001 0.001" />
      </geometry>
      <material name="silver" />
    </visual>
    <collision>
      <origin rpy="0 0 0" xyz="0 0 0.06" />
      <geometry>
        <cylinder length="0.10" radius="0.035" />
      </geometry>
    </collision>
  </link>
  <joint name="hip_pitch_l" type="revolute">
    <origin rpy="3.141593 1.308997 -3.141593" xyz="0.074290 0.000000 0.065550" />
    <parent link="pelvis" />
    <child link="hip_pitch_l" />
    <axis xyz="0 0 1" />
    <limit effort="150" lower="-3.1416" upper="3.1416" velocity="5" />
    <dynamics damping="5.0" friction="0.1" />
  </joint>
  <link name="hip_roll_l">
    <inertial>
      <origin rpy="0 0 0" xyz="3.5e-05 -3e-08 0.03968" />
      <mass value="1.319" />
      <inertia ixx="0.00871" ixy="0" ixz="0" iyy="0.01037" iyz="0" izz="0.00721" />
    </inertial>
    <visual>
      <origin rpy="0 0 0" xyz="0 0 0" />
      <geometry>
        <mesh filename="file:///home/me/clean_ws/src/XP_robot/meshes/hip_roll_l.stl"
          scale="0.001 0.001 0.001" />
      </geometry>
      <material name="silver" />
    </visual>
    <collision>
      <origin rpy="0 0 0" xyz="0 0 0.04" />
      <geometry>
        <cylinder length="0.08" radius="0.035" />
      </geometry>
    </collision>
  </link>
  <link name="hip_roll_l_frame" />
  <joint name="hip_roll_l" type="revolute">
    <origin rpy="1.832596 0.000000 -1.570796" xyz="-0.000097 -0.022500 0.077909" />
    <parent link="hip_pitch_l" />
    <child link="hip_roll_l_frame" />
    <axis xyz="1 0 0" />
    <limit effort="120" lower="-0.292" upper="2.35" velocity="5" />
    <dynamics damping="5.0" friction="0.1" />
  </joint>
  <joint name="hip_roll_l_fix" type="fixed">
    <origin rpy="0 0 0" xyz="-0.022500 0.000000 -0.143000" />
    <parent link="hip_roll_l_frame" />
    <child link="hip_roll_l" />
  </joint>
  <link name="thigh_l">
    <inertial>
      <origin rpy="0 0 0" xyz="0.01437 -0.13463 -0.04238" />
      <mass value="2.264" />
      <inertia ixx="0.04565" ixy="0" ixz="0" iyy="0.04875" iyz="0" izz="0.00823" />
    </inertial>
    <visual>
      <origin rpy="0 0 0" xyz="0 0 0" />
      <geometry>
        <mesh filename="file:///home/me/clean_ws/src/XP_robot/meshes/thigh_l.stl"
          scale="0.001 0.001 0.001" />
      </geometry>
      <material name="silver" />
    </visual>
    <collision>
      <origin rpy="0 0 0" xyz="0.01 -0.13 0.06" />
      <geometry>
        <cylinder length="0.21" radius="0.04" />
      </geometry>
    </collision>
  </link>
  <link name="thigh_yaw_l_frame" />
  <joint name="thigh_yaw_l" type="revolute">
    <origin rpy="0 0 0" xyz="0.000000 0.000000 -0.005500" />
    <parent link="hip_roll_l" />
    <child link="thigh_yaw_l_frame" />
    <axis xyz="0 0 -1" />
    <limit effort="80" lower="-3.1416" upper="3.1416" velocity="5" />
    <dynamics damping="5.0" friction="0.1" />
  </joint>
  <joint name="thigh_yaw_l_fix" type="fixed">
    <origin rpy="0 0 0" xyz="-0.011580 0.131790 -0.163040" />
    <parent link="thigh_yaw_l_frame" />
    <child link="thigh_l" />
  </joint>
  <link name="leg_shank_l">
    <inertial>
      <origin rpy="0 0 0" xyz="-0.14872 -0.00406 -0.50123" />
      <mass value="1.446" />
      <inertia ixx="0.02297" ixy="0" ixz="0" iyy="0.02434" iyz="0" izz="0.00263" />
    </inertial>
    <visual>
      <origin rpy="0 0 0" xyz="0 0 0" />
      <geometry>
        <mesh filename="file:///home/me/clean_ws/src/XP_robot/meshes/leg_shank_l.stl"
          scale="0.001 0.001 0.001" />
      </geometry>
      <material name="silver" />
    </visual>
    <collision>
      <origin rpy="0 0 0" xyz="-0.148 -0.004 -0.50" />
      <geometry>
        <cylinder length="0.32" radius="0.035" />
      </geometry>
    </collision>
  </link>
  <link name="knee_pitch_l_frame" />
  <joint name="knee_pitch_l" type="revolute">
    <origin rpy="-0.002816 0.000696 1.571419" xyz="0.011589 -0.160545 -0.086954" />
    <parent link="thigh_l" />
    <child link="knee_pitch_l_frame" />
    <axis xyz="-1 0 0" />
    <limit effort="200" lower="-1.5708" upper="0.0" velocity="5" />
    <dynamics damping="5.0" friction="0.1" />
  </joint>
  <joint name="knee_pitch_l_fix" type="fixed">
    <origin rpy="0 0 0" xyz="0.177560 0.000500 0.352910" />
    <parent link="knee_pitch_l_frame" />
    <child link="leg_shank_l" />
  </joint>
  <link name="uj_l">
    <inertial>
      <origin rpy="0 0 0" xyz="0 0 -5.22e-05" />
      <mass value="0.098" />
      <inertia ixx="1.0e-05" ixy="0" ixz="0" iyy="8.6e-06" iyz="0" izz="1.6e-05" />
    </inertial>
    <visual>
      <origin rpy="0 0 0" xyz="0 0 0" />
      <geometry>
        <mesh filename="file:///home/me/clean_ws/src/XP_robot/meshes/uj_l.stl"
          scale="0.001 0.001 0.001" />
      </geometry>
      <material name="silver" />
    </visual>
    <collision>
      <origin rpy="0 0 0" xyz="0 0 0" />
      <geometry>
        <sphere radius="0.025" />
      </geometry>
    </collision>
  </link>
  <link name="ankle_pitch_l_frame" />
  <joint name="ankle_pitch_l" type="revolute">
    <origin rpy="3.140898 -0.002813 1.570170" xyz="-0.165570 0.000677 -0.700162" />
    <parent link="leg_shank_l" />
    <child link="ankle_pitch_l_frame" />
    <axis xyz="0 1 0" />
    <limit effort="80" lower="-0.6981" upper="0.6981" velocity="5" />
    <dynamics damping="5.0" friction="0.1" />
  </joint>
  <joint name="ankle_pitch_l_fix" type="fixed">
    <origin rpy="0 0 0" xyz="0.000000 0.017000 0.000000" />
    <parent link="ankle_pitch_l_frame" />
    <child link="uj_l" />
  </joint>
  <link name="foot_l">
    <inertial>
      <origin rpy="0 0 0" xyz="-6.6e-11 0.02074 -4.8e-04" />
      <mass value="0.365" />
      <inertia ixx="8.3e-04" ixy="0" ixz="0" iyy="2.8e-04" iyz="0" izz="9.5e-04" />
    </inertial>
    <visual>
      <origin rpy="0 0 0" xyz="0 0 0" />
      <geometry>
        <mesh filename="file:///home/me/clean_ws/src/XP_robot/meshes/foot_l.stl"
          scale="0.001 0.001 0.001" />
      </geometry>
      <material name="silver" />
    </visual>
    <collision>
      <origin rpy="0 0 0" xyz="0 0.055 -0.048" />
      <geometry>
        <box size="0.06 0.14 0.02" />
      </geometry>
    </collision>
  </link>
  <link name="ankle_roll_l_frame" />
  <joint name="ankle_roll_l" type="revolute">
    <origin rpy="-3.141593 0.000000 1.570796" xyz="0.017000 -0.000000 0.000000" />
    <parent link="uj_l" />
    <child link="ankle_roll_l_frame" />
    <axis xyz="0 -1 0" />
    <limit effort="60" lower="-0.3491" upper="0.3491" velocity="5" />
    <dynamics damping="5.0" friction="0.1" />
  </joint>
  <joint name="ankle_roll_l_fix" type="fixed">
    <origin rpy="0 0 0" xyz="0.000000 -0.040500 -0.030990" />
    <parent link="ankle_roll_l_frame" />
    <child link="foot_l" />
  </joint>
  <!-- ══ TORSO ══ -->
  <link name="torso">
    <inertial>
      <origin rpy="0 0 0" xyz="0.00217 0.00139 0.22276" />
      <mass value="4.529" />
      <inertia ixx="0.13599" ixy="0" ixz="0" iyy="0.20074" iyz="0" izz="0.11603" />
    </inertial>
    <visual>
      <origin rpy="0 0 0" xyz="0 0 0" />
      <geometry>
        <mesh filename="file:///home/me/clean_ws/src/XP_robot/meshes/torso.stl"
          scale="0.001 0.001 0.001" />
      </geometry>
      <material name="silver" />
    </visual>
    <collision>
      <origin rpy="0 0 0" xyz="0 0 0.18" />
      <geometry>
        <box size="0.24 0.20 0.36" />
      </geometry>
    </collision>
  </link>
  <joint name="torso_yaw" type="revolute">
    <origin rpy="0.000000 0.000000 3.141593" xyz="0.000000 0.000000 0.213090" />
    <parent link="pelvis" />
    <child link="torso" />
    <axis xyz="0 0 -1" />
    <limit effort="100" lower="-3.1416" upper="3.1416" velocity="5" />
    <dynamics damping="5.0" friction="0.1" />
  </joint>
  <!-- ══ RIGHT ARM ══ -->
  <link name="shoulder_pitch_r">
    <inertial>
      <origin rpy="0 0 0" xyz="0.00218 -0.00191 0.02403" />
      <mass value="0.929" />
      <inertia ixx="0.00327" ixy="0" ixz="0" iyy="0.00493" iyz="0" izz="0.00368" />
    </inertial>
    <visual>
      <origin rpy="0 0 0" xyz="0 0 0" />
      <geometry>
        <mesh filename="file:///home/me/clean_ws/src/XP_robot/meshes/shoulder_pitch_r.stl"
          scale="0.001 0.001 0.001" />
      </geometry>
      <material name="silver" />
    </visual>
    <collision>
      <origin rpy="0 0 0" xyz="0.075 0 0.024" />
      <geometry>
        <sphere radius="0.04" />
      </geometry>
    </collision>
  </link>
  <link name="shoulder_pitch_r_frame" />
  <joint name="shoulder_pitch_r" type="revolute">
    <origin rpy="0.000000 0.000000 -3.141593" xyz="0.146020 0.000000 0.289500" />
    <parent link="torso" />
    <child link="shoulder_pitch_r_frame" />
    <axis xyz="-1 0 0" />
    <limit effort="100" lower="-3.1416" upper="3.1416" velocity="5" />
    <dynamics damping="5.0" friction="0.1" />
  </joint>
  <joint name="shoulder_pitch_r_fix" type="fixed">
    <origin rpy="0 0 0" xyz="-0.075500 0.004280 -0.024030" />
    <parent link="shoulder_pitch_r_frame" />
    <child link="shoulder_pitch_r" />
  </joint>
  <link name="shoulder_roll_r">
    <inertial>
      <origin rpy="0 0 0" xyz="3.74e-04 -8.4e-07 0.02539" />
      <mass value="0.640" />
      <inertia ixx="0.00132" ixy="0" ixz="0" iyy="0.00173" iyz="0" izz="0.00156" />
    </inertial>
    <visual>
      <origin rpy="0 0 0" xyz="0 0 0" />
      <geometry>
        <mesh filename="file:///home/me/clean_ws/src/XP_robot/meshes/shoulder_roll_r.stl"
          scale="0.001 0.001 0.001" />
      </geometry>
      <material name="silver" />
    </visual>
    <collision>
      <origin rpy="0 0 0" xyz="0 0 0.05" />
      <geometry>
        <cylinder length="0.08" radius="0.025" />
      </geometry>
    </collision>
  </link>
  <link name="shoulder_roll_r_frame" />
  <joint name="shoulder_roll_r" type="revolute">
    <origin rpy="0.000000 0.000000 -1.570796" xyz="0.000000 -0.044530 0.024040" />
    <parent link="shoulder_pitch_r" />
    <child link="shoulder_roll_r_frame" />
    <axis xyz="-1 0 0" />
    <limit effort="100" lower="-0.0873" upper="3.3161" velocity="5" />
    <dynamics damping="5.0" friction="0.1" />
  </joint>
  <joint name="shoulder_roll_r_fix" type="fixed">
    <origin rpy="0 0 0" xyz="-0.042250 0.000000 -0.107340" />
    <parent link="shoulder_roll_r_frame" />
    <child link="shoulder_roll_r" />
  </joint>
  <link name="bicep_r">
    <inertial>
      <origin rpy="0 0 0" xyz="4.67e-04 -4.75e-03 -0.09020" />
      <mass value="0.648" />
      <inertia ixx="0.00380" ixy="0" ixz="0" iyy="0.00362" iyz="0" izz="0.00161" />
    </inertial>
    <visual>
      <origin rpy="0 0 0" xyz="0 0 0" />
      <geometry>
        <mesh filename="file:///home/me/clean_ws/src/XP_robot/meshes/bicep_r.stl"
          scale="0.001 0.001 0.001" />
      </geometry>
      <material name="silver" />
    </visual>
    <collision>
      <origin rpy="0 0 0" xyz="0.0005 -0.005 -0.045" />
      <geometry>
        <cylinder length="0.14" radius="0.028" />
      </geometry>
    </collision>
  </link>
  <link name="elbow_yaw_r_frame" />
  <joint name="elbow_yaw_r" type="revolute">
    <origin rpy="0.000000 0.000000 1.570796" xyz="0.000010 0.000000 -0.004000" />
    <parent link="shoulder_roll_r" />
    <child link="elbow_yaw_r_frame" />
    <axis xyz="0 0 -1" />
    <limit effort="50" lower="-3.1416" upper="3.1416" velocity="5" />
    <dynamics damping="5.0" friction="0.1" />
  </joint>
  <joint name="elbow_yaw_r_fix" type="fixed">
    <origin rpy="0 0 0" xyz="0.000000 0.006160 -0.031000" />
    <parent link="elbow_yaw_r_frame" />
    <child link="bicep_r" />
  </joint>
  <link name="forearm_r">
    <inertial>
      <origin rpy="0 0 0" xyz="0.00311 -0.03400 -0.10268" />
      <mass value="0.370" />
      <inertia ixx="0.00122" ixy="0" ixz="0" iyy="0.00130" iyz="0" izz="3.09e-04" />
    </inertial>
    <visual>
      <origin rpy="0 0 0" xyz="0 0 0" />
      <geometry>
        <mesh filename="file:///home/me/clean_ws/src/XP_robot/meshes/forearm_r.stl"
          scale="0.001 0.001 0.001" />
      </geometry>
      <material name="silver" />
    </visual>
    <collision>
      <origin rpy="0 0 0" xyz="0.003 -0.034 -0.103" />
      <geometry>
        <cylinder length="0.14" radius="0.022" />
      </geometry>
    </collision>
  </link>
  <link name="elbow_pitch_r_frame" />
  <joint name="elbow_pitch_r" type="revolute">
    <origin rpy="0.000000 0.000000 0.000000" xyz="-0.032000 -0.006150 -0.099990" />
    <parent link="bicep_r" />
    <child link="elbow_pitch_r_frame" />
    <axis xyz="1 0 0" />
    <limit effort="50" lower="-2.5307" upper="0.0" velocity="5" />
    <dynamics damping="5.0" friction="0.1" />
  </joint>
  <joint name="elbow_pitch_r_fix" type="fixed">
    <origin rpy="0 0 0" xyz="0.028390 0.034520 0.001080" />
    <parent link="elbow_pitch_r_frame" />
    <child link="forearm_r" />
  </joint>
  <!-- ══ LEFT ARM ══ -->
  <link name="shoulder_pitch_l">
    <inertial>
      <origin rpy="0 0 0" xyz="0.00218 -0.00191 0.02403" />
      <mass value="0.929" />
      <inertia ixx="0.00327" ixy="0" ixz="0" iyy="0.00493" iyz="0" izz="0.00368" />
    </inertial>
    <visual>
      <origin rpy="0 0 0" xyz="0 0 0" />
      <geometry>
        <mesh filename="file:///home/me/clean_ws/src/XP_robot/meshes/shoulder_pitch_l.stl"
          scale="0.001 0.001 0.001" />
      </geometry>
      <material name="silver" />
    </visual>
    <collision>
      <origin rpy="0 0 0" xyz="0.075 0 0.024" />
      <geometry>
        <sphere radius="0.04" />
      </geometry>
    </collision>
  </link>
  <link name="shoulder_pitch_l_frame" />
  <joint name="shoulder_pitch_l" type="revolute">
    <origin rpy="-3.141593 0.000000 0.000000" xyz="-0.146020 0.000000 0.289510" />
    <parent link="torso" />
    <child link="shoulder_pitch_l_frame" />
    <axis xyz="1 0 0" />
    <limit effort="100" lower="-3.1416" upper="3.1416" velocity="5" />
    <dynamics damping="5.0" friction="0.1" />
  </joint>
  <joint name="shoulder_pitch_l_fix" type="fixed">
    <origin rpy="0 0 0" xyz="-0.075500 0.004280 -0.024030" />
    <parent link="shoulder_pitch_l_frame" />
    <child link="shoulder_pitch_l" />
  </joint>
  <link name="shoulder_roll_l">
    <inertial>
      <origin rpy="0 0 0" xyz="3.74e-04 -8.4e-07 0.02539" />
      <mass value="0.640" />
      <inertia ixx="0.00132" ixy="0" ixz="0" iyy="0.00173" iyz="0" izz="0.00156" />
    </inertial>
    <visual>
      <origin rpy="0 0 0" xyz="0 0 0" />
      <geometry>
        <mesh filename="file:///home/me/clean_ws/src/XP_robot/meshes/shoulder_roll_l.stl"
          scale="0.001 0.001 0.001" />
      </geometry>
      <material name="silver" />
    </visual>
    <collision>
      <origin rpy="0 0 0" xyz="0 0 0.05" />
      <geometry>
        <cylinder length="0.08" radius="0.025" />
      </geometry>
    </collision>
  </link>
  <link name="shoulder_roll_l_frame" />
  <joint name="shoulder_roll_l" type="revolute">
    <origin rpy="-3.141593 0.000000 -1.570796" xyz="0.000000 -0.044530 0.024030" />
    <parent link="shoulder_pitch_l" />
    <child link="shoulder_roll_l_frame" />
    <axis xyz="-1 0 0" />
    <limit effort="100" lower="-3.3161" upper="0.0873" velocity="5" />
    <dynamics damping="5.0" friction="0.1" />
  </joint>
  <joint name="shoulder_roll_l_fix" type="fixed">
    <origin rpy="0 0 0" xyz="-0.042250 0.000000 -0.107340" />
    <parent link="shoulder_roll_l_frame" />
    <child link="shoulder_roll_l" />
  </joint>
  <link name="bicep_l">
    <inertial>
      <origin rpy="0 0 0" xyz="4.67e-04 -4.75e-03 -0.09020" />
      <mass value="0.648" />
      <inertia ixx="0.00380" ixy="0" ixz="0" iyy="0.00362" iyz="0" izz="0.00161" />
    </inertial>
    <visual>
      <origin rpy="0 0 0" xyz="0 0 0" />
      <geometry>
        <mesh filename="file:///home/me/clean_ws/src/XP_robot/meshes/bicep_l.stl"
          scale="0.001 0.001 0.001" />
      </geometry>
      <material name="silver" />
    </visual>
    <collision>
      <origin rpy="0 0 0" xyz="0.0005 -0.005 -0.045" />
      <geometry>
        <cylinder length="0.14" radius="0.028" />
      </geometry>
    </collision>
  </link>
  <link name="elbow_yaw_l_frame" />
  <joint name="elbow_yaw_l" type="revolute">
    <origin rpy="0.000000 0.000000 1.570796" xyz="0.000010 0.000000 -0.004000" />
    <parent link="shoulder_roll_l" />
    <child link="elbow_yaw_l_frame" />
    <axis xyz="0 0 -1" />
    <limit effort="50" lower="-3.1416" upper="3.1416" velocity="5" />
    <dynamics damping="5.0" friction="0.1" />
  </joint>
  <joint name="elbow_yaw_l_fix" type="fixed">
    <origin rpy="0 0 0" xyz="0.000000 0.006160 -0.031000" />
    <parent link="elbow_yaw_l_frame" />
    <child link="bicep_l" />
  </joint>
  <link name="forearm_l">
    <inertial>
      <origin rpy="0 0 0" xyz="0.00311 -0.03400 -0.10268" />
      <mass value="0.370" />
      <inertia ixx="0.00122" ixy="0" ixz="0" iyy="0.00130" iyz="0" izz="3.09e-04" />
    </inertial>
    <visual>
      <origin rpy="0 0 0" xyz="0 0 0" />
      <geometry>
        <mesh filename="file:///home/me/clean_ws/src/XP_robot/meshes/forearm_l.stl"
          scale="0.001 0.001 0.001" />
      </geometry>
      <material name="silver" />
    </visual>
    <collision>
      <origin rpy="0 0 0" xyz="0.003 -0.034 -0.103" />
      <geometry>
        <cylinder length="0.14" radius="0.022" />
      </geometry>
    </collision>
  </link>
  <link name="elbow_pitch_l_frame" />
  <joint name="elbow_pitch_l" type="revolute">
    <origin rpy="0.000000 0.000000 0.000000" xyz="-0.032000 -0.006150 -0.099990" />
    <parent link="bicep_l" />
    <child link="elbow_pitch_l_frame" />
    <axis xyz="1 0 0" />
    <limit effort="50" lower="-2.5307" upper="0.0" velocity="5" />
    <dynamics damping="5.0" friction="0.1" />
  </joint>
  <joint name="elbow_pitch_l_fix" type="fixed">
    <origin rpy="0 0 0" xyz="0.028390 0.034520 0.001080" />
    <parent link="elbow_pitch_l_frame" />
    <child link="forearm_l" />
  </joint>
  <!-- ══════════════════════════════════════════════════════════════════════════
         RIGHT HAND
         All collision geometries are primitive shapes (box / cylinder / sphere).
         Visual meshes are unchanged.
    ══════════════════════════════════════════════════════════════════════════ -->
  <!-- Palm: flat box covering the hand body (~80 × 35 × 20 mm) -->
  <link name="R_palm">
    <inertial>
      <origin rpy="0 0 0" xyz="0 0 0" />
      <mass value="0.5" />
      <inertia ixx="2e-4" ixy="0" ixz="0" iyy="2e-4" iyz="0" izz="1e-4" />
    </inertial>
    <visual>
      <origin rpy="0 0 0" xyz="0 0 0" />
      <geometry>
        <mesh filename="file:///home/me/clean_ws/src/XP_robot/meshes/R_palm.stl"
          scale="0.001 0.001 0.001" />
      </geometry>
      <material name="silver" />
    </visual>
    <collision>
      <origin rpy="0 0 0" xyz="0.0 0.0 0.09" />
      <geometry>
        <box size="0.080 0.020 0.090" />
      </geometry>
    </collision>
  </link>
  <joint name="hand_roll_r" type="revolute">
    <origin rpy="-3.141593 0 -3.141593" xyz="0.003609 -0.034524 -0.153085" />
    <parent link="forearm_r" />
    <child link="R_palm" />
    <axis xyz="0 0 1" />
    <limit effort="10" lower="-3.1416" upper="3.1416" velocity="5" />
    <dynamics damping="0.5" friction="0.1" />
  </joint>
  <!-- Right thumb — 4 phalanges, each a small cylinder (r=8mm) -->
  <link name="R_thumb_yaw_link">
    <inertial>
      <origin rpy="0 0 0" xyz="0 0 0" />
      <mass value="0.010" />
      <inertia ixx="1e-6" ixy="0" ixz="0" iyy="1e-6" iyz="0" izz="1e-6" />
    </inertial>
    <visual>
      <origin rpy="0 0 0" xyz="-0.032500 -0.031212 -0.088490" />
      <geometry>
        <mesh filename="file:///home/me/clean_ws/src/XP_robot/meshes/R_thumb_yaw_link.stl"
          scale="0.001 0.001 0.001" />
      </geometry>
      <material name="silver" />
    </visual>
    <collision>
      <origin rpy="0 0 0" xyz="0 0 -0.013" />
      <geometry>
        <cylinder length="0.026" radius="0.008" />
      </geometry>
    </collision>
  </link>
  <joint name="R_thumb_yaw" type="revolute">
    <origin rpy="-3.141593 0 3.141593" xyz="0.023000 -0.011000 0.055250" />
    <parent link="R_palm" />
    <child link="R_thumb_yaw_link" />
    <axis xyz="0 0 1" />
    <limit effort="5" lower="-0.60" upper="0.75" velocity="5" />
    <dynamics damping="0.1" friction="0.0" />
  </joint>
  <link name="R_thumb_cmc_link">
    <inertial>
      <origin rpy="0 0 0" xyz="0 0 0" />
      <mass value="0.008" />
      <inertia ixx="1e-6" ixy="0" ixz="0" iyy="1e-6" iyz="0" izz="1e-6" />
    </inertial>
    <visual>
      <origin rpy="0 0 0" xyz="-0.037250 -0.019212 -0.081660" />
      <geometry>
        <mesh filename="file:///home/me/clean_ws/src/XP_robot/meshes/R_thumb_cmc_link.stl"
          scale="0.001 0.001 0.001" />
      </geometry>
      <material name="silver" />
    </visual>
    <collision>
      <origin rpy="1.5708 0 0" xyz="0 -0.031 0" />
      <geometry>
        <cylinder length="0.030" radius="0.008" />
      </geometry>
    </collision>
  </link>
  <joint name="R_thumb_cmc" type="revolute">
    <origin rpy="0 0 0" xyz="0.004750 -0.012000 -0.006830" />
    <parent link="R_thumb_yaw_link" />
    <child link="R_thumb_cmc_link" />
    <axis xyz="1 0 0" />
    <limit effort="5" lower="-0.60" upper="0.70" velocity="5" />
    <dynamics damping="0.1" friction="0.0" />
  </joint>
  <link name="R_thumb_mcp_link">
    <inertial>
      <origin rpy="0 0 0" xyz="0 0 0" />
      <mass value="0.007" />
      <inertia ixx="1e-6" ixy="0" ixz="0" iyy="1e-6" iyz="0" izz="1e-6" />
    </inertial>
    <visual>
      <origin rpy="0 0 0" xyz="-0.037200 0.042788 -0.073660" />
      <geometry>
        <mesh filename="file:///home/me/clean_ws/src/XP_robot/meshes/R_thumb_mcp_link.stl"
          scale="0.001 0.001 0.001" />
      </geometry>
      <material name="silver" />
    </visual>
    <collision>
      <origin rpy="1.5708 0 0" xyz="0 -0.010 0.009" />
      <geometry>
        <cylinder length="0.019" radius="0.008" />
      </geometry>
    </collision>
  </link>
  <joint name="R_thumb_mcp" type="revolute">
    <origin rpy="0 0 0" xyz="-0.000050 -0.062000 -0.008000" />
    <parent link="R_thumb_cmc_link" />
    <child link="R_thumb_mcp_link" />
    <axis xyz="-1 0 0" />
    <limit effort="5" lower="-1.57" upper="0.00" velocity="5" />
    <dynamics damping="0.1" friction="0.0" />
  </joint>
  <link name="R_thumb_ip_link">
    <inertial>
      <origin rpy="0 0 0" xyz="0 0 0" />
      <mass value="0.006" />
      <inertia ixx="1e-6" ixy="0" ixz="0" iyy="1e-6" iyz="0" izz="1e-6" />
    </inertial>
    <visual>
      <origin rpy="0 0 0" xyz="-0.037200 0.061788 -0.073660" />
      <geometry>
        <mesh filename="file:///home/me/clean_ws/src/XP_robot/meshes/R_thumb_ip_link.stl"
          scale="0.001 0.001 0.001" />
      </geometry>
      <material name="silver" />
    </visual>
    <collision>
      <origin rpy="1.5708 0 0" xyz="0 -0.010 0.009" />
      <geometry>
        <cylinder length="0.018" radius="0.007" />
      </geometry>
    </collision>
  </link>
  <joint name="R_thumb_ip" type="revolute">
    <origin rpy="0 0 0" xyz="-0.000000 -0.019000 0.000000" />
    <parent link="R_thumb_mcp_link" />
    <child link="R_thumb_ip_link" />
    <axis xyz="-1 0 0" />
    <limit effort="5" lower="-0.95" upper="0.13" velocity="5" />
    <dynamics damping="0.1" friction="0.0" />
  </joint>
  <!-- Right pinky — 3 phalanges (r=6mm) -->
  <link name="R_pinky_mcp_link">
    <inertial>
      <origin rpy="0 0 0" xyz="0 0 0" />
      <mass value="0.008" />
      <inertia ixx="1e-6" ixy="0" ixz="0" iyy="1e-6" iyz="0" izz="1e-6" />
    </inertial>
    <visual>
      <origin rpy="0 0 0" xyz="0.035055 0.000670 -0.134339" />
      <geometry>
        <mesh filename="file:///home/me/clean_ws/src/XP_robot/meshes/R_pinky_mcp_link.stl"
          scale="0.001 0.001 0.001" />
      </geometry>
      <material name="silver" />
    </visual>
    <collision>
      <origin rpy="0 0 0" xyz="0 0 0.02" />
      <geometry>
        <cylinder length="0.028" radius="0.006" />
      </geometry>
    </collision>
  </link>
  <joint name="R_pinky_mcp" type="revolute">
    <origin rpy="0 0 0" xyz="-0.035055 -0.000670 0.134339" />
    <parent link="R_palm" />
    <child link="R_pinky_mcp_link" />
    <axis xyz="1 0 0" />
    <limit effort="5" lower="-0.50" upper="1.57" velocity="5" />
    <dynamics damping="0.1" friction="0.0" />
  </joint>
  <link name="R_pinky_pip_link">
    <inertial>
      <origin rpy="0 0 0" xyz="0 0 0" />
      <mass value="0.006" />
      <inertia ixx="1e-6" ixy="0" ixz="0" iyy="1e-6" iyz="0" izz="1e-6" />
    </inertial>
    <visual>
      <origin rpy="0 0 0" xyz="0.037973 0.000665 -0.162106" />
      <geometry>
        <mesh filename="file:///home/me/clean_ws/src/XP_robot/meshes/R_pinky_pip_link.stl"
          scale="0.001 0.001 0.001" />
      </geometry>
      <material name="silver" />
    </visual>
    <collision>
      <origin rpy="0 0 0" xyz="0 0 0.017" />
      <geometry>
        <cylinder length="0.021" radius="0.006" />
      </geometry>
    </collision>
  </link>
  <joint name="R_pinky_pip" type="revolute">
    <origin rpy="0 0 0" xyz="-0.002918 0.000005 0.027767" />
    <parent link="R_pinky_mcp_link" />
    <child link="R_pinky_pip_link" />
    <axis xyz="1 0 0" />
    <limit effort="5" lower="-0.13" upper="1.57" velocity="5" />
    <dynamics damping="0.1" friction="0.0" />
  </joint>
  <link name="R_pinky_dip_link">
    <inertial>
      <origin rpy="0 0 0" xyz="0 0 0" />
      <mass value="0.005" />
      <inertia ixx="1e-6" ixy="0" ixz="0" iyy="1e-6" iyz="0" izz="1e-6" />
    </inertial>
    <visual>
      <origin rpy="0 0 0" xyz="0.040168 0.000298 -0.182989" />
      <geometry>
        <mesh filename="file:///home/me/clean_ws/src/XP_robot/meshes/R_pinky_dip_link.stl"
          scale="0.001 0.001 0.001" />
      </geometry>
      <material name="silver" />
    </visual>
    <collision>
      <origin rpy="0 0 0" xyz="0 0 0.015" />
      <geometry>
        <cylinder length="0.016" radius="0.005" />
      </geometry>
    </collision>
  </link>
  <joint name="R_pinky_dip" type="revolute">
    <origin rpy="0 0 0" xyz="-0.002195 0.000367 0.020882" />
    <parent link="R_pinky_pip_link" />
    <child link="R_pinky_dip_link" />
    <axis xyz="1 0 0" />
    <limit effort="5" lower="-0.30" upper="1.80" velocity="5" />
    <dynamics damping="0.1" friction="0.0" />
  </joint>
  <!-- Right ring — 3 phalanges (r=6mm) -->
  <link name="R_ring_mcp_link">
    <inertial>
      <origin rpy="0 0 0" xyz="0 0 0" />
      <mass value="0.008" />
      <inertia ixx="1e-6" ixy="0" ixz="0" iyy="1e-6" iyz="0" izz="1e-6" />
    </inertial>
    <visual>
      <origin rpy="0 0 0" xyz="0.014359 0.000670 -0.140268" />
      <geometry>
        <mesh filename="file:///home/me/clean_ws/src/XP_robot/meshes/R_ring_mcp_link.stl"
          scale="0.001 0.001 0.001" />
      </geometry>
      <material name="silver" />
    </visual>
    <collision>
      <origin rpy="0 0 0" xyz="0 0 0.014" />
      <geometry>
        <cylinder length="0.028" radius="0.006" />
      </geometry>
    </collision>
  </link>
  <joint name="R_ring_mcp" type="revolute">
    <origin rpy="0 0 0" xyz="-0.014359 -0.000670 0.140268" />
    <parent link="R_palm" />
    <child link="R_ring_mcp_link" />
    <axis xyz="1 0 0" />
    <limit effort="5" lower="-0.50" upper="1.70" velocity="5" />
    <dynamics damping="0.1" friction="0.0" />
  </joint>
  <link name="R_ring_pip_link">
    <inertial>
      <origin rpy="0 0 0" xyz="0 0 0" />
      <mass value="0.006" />
      <inertia ixx="1e-6" ixy="0" ixz="0" iyy="1e-6" iyz="0" izz="1e-6" />
    </inertial>
    <visual>
      <origin rpy="0 0 0" xyz="0.015820 0.001152 -0.168146" />
      <geometry>
        <mesh filename="file:///home/me/clean_ws/src/XP_robot/meshes/R_ring_pip_link.stl"
          scale="0.001 0.001 0.001" />
      </geometry>
      <material name="silver" />
    </visual>
    <collision>
      <origin rpy="0 0 0" xyz="0 0 0.011" />
      <geometry>
        <cylinder length="0.021" radius="0.006" />
      </geometry>
    </collision>
  </link>
  <joint name="R_ring_pip" type="revolute">
    <origin rpy="0 0 0" xyz="-0.001461 -0.000482 0.027878" />
    <parent link="R_ring_mcp_link" />
    <child link="R_ring_pip_link" />
    <axis xyz="1 0 0" />
    <limit effort="5" lower="-0.13" upper="1.57" velocity="5" />
    <dynamics damping="0.1" friction="0.0" />
  </joint>
  <link name="R_ring_dip_link">
    <inertial>
      <origin rpy="0 0 0" xyz="0 0 0" />
      <mass value="0.005" />
      <inertia ixx="1e-6" ixy="0" ixz="0" iyy="1e-6" iyz="0" izz="1e-6" />
    </inertial>
    <visual>
      <origin rpy="0 0 0" xyz="0.016919 0.001152 -0.189117" />
      <geometry>
        <mesh filename="file:///home/me/clean_ws/src/XP_robot/meshes/R_ring_dip_link.stl"
          scale="0.001 0.001 0.001" />
      </geometry>
      <material name="silver" />
    </visual>
    <collision>
      <origin rpy="0 0 0" xyz="0 0 0.009" />
      <geometry>
        <cylinder length="0.016" radius="0.005" />
      </geometry>
    </collision>
  </link>
  <joint name="R_ring_dip" type="revolute">
    <origin rpy="0 0 0" xyz="-0.001099 -0.000000 0.020971" />
    <parent link="R_ring_pip_link" />
    <child link="R_ring_dip_link" />
    <axis xyz="1 0 0" />
    <limit effort="5" lower="-0.30" upper="1.90" velocity="5" />
    <dynamics damping="0.1" friction="0.0" />
  </joint>
  <!-- Right middle — 3 phalanges (r=6mm) -->
  <link name="R_middle_mcp_link">
    <inertial>
      <origin rpy="0 0 0" xyz="0 0 0" />
      <mass value="0.008" />
      <inertia ixx="1e-6" ixy="0" ixz="0" iyy="1e-6" iyz="0" izz="1e-6" />
    </inertial>
    <visual>
      <origin rpy="0 0 0" xyz="-0.006120 0.000670 -0.141014" />
      <geometry>
        <mesh filename="file:///home/me/clean_ws/src/XP_robot/meshes/R_middle_mcp_link.stl"
          scale="0.001 0.001 0.001" />
      </geometry>
      <material name="silver" />
    </visual>
    <collision>
      <origin rpy="0 0 0" xyz="0 0 0.014" />
      <geometry>
        <cylinder length="0.028" radius="0.006" />
      </geometry>
    </collision>
  </link>
  <joint name="R_middle_mcp" type="revolute">
    <origin rpy="0 0 0" xyz="0.006120 -0.000670 0.141014" />
    <parent link="R_palm" />
    <child link="R_middle_mcp_link" />
    <axis xyz="1 0 0" />
    <limit effort="5" lower="-0.50" upper="1.70" velocity="5" />
    <dynamics damping="0.1" friction="0.0" />
  </joint>
  <link name="R_middle_pip_link">
    <inertial>
      <origin rpy="0 0 0" xyz="0 0 0" />
      <mass value="0.006" />
      <inertia ixx="1e-6" ixy="0" ixz="0" iyy="1e-6" iyz="0" izz="1e-6" />
    </inertial>
    <visual>
      <origin rpy="0 0 0" xyz="-0.006120 0.000665 -0.168934" />
      <geometry>
        <mesh filename="file:///home/me/clean_ws/src/XP_robot/meshes/R_middle_pip_link.stl"
          scale="0.001 0.001 0.001" />
      </geometry>
      <material name="silver" />
    </visual>
    <collision>
      <origin rpy="0 0 0" xyz="0 0 0.011" />
      <geometry>
        <cylinder length="0.021" radius="0.006" />
      </geometry>
    </collision>
  </link>
  <joint name="R_middle_pip" type="revolute">
    <origin rpy="0 0 0" xyz="-0.000000 0.000005 0.027920" />
    <parent link="R_middle_mcp_link" />
    <child link="R_middle_pip_link" />
    <axis xyz="1 0 0" />
    <limit effort="5" lower="-0.13" upper="1.57" velocity="5" />
    <dynamics damping="0.1" friction="0.0" />
  </joint>
  <link name="R_middle_dip_link">
    <inertial>
      <origin rpy="0 0 0" xyz="0 0 0" />
      <mass value="0.005" />
      <inertia ixx="1e-6" ixy="0" ixz="0" iyy="1e-6" iyz="0" izz="1e-6" />
    </inertial>
    <visual>
      <origin rpy="0 0 0" xyz="-0.006120 0.000298 -0.189931" />
      <geometry>
        <mesh filename="file:///home/me/clean_ws/src/XP_robot/meshes/R_middle_dip_link.stl"
          scale="0.001 0.001 0.001" />
      </geometry>
      <material name="silver" />
    </visual>
    <collision>
      <origin rpy="0 0 0" xyz="0 0 0.009" />
      <geometry>
        <cylinder length="0.016" radius="0.005" />
      </geometry>
    </collision>
  </link>
  <joint name="R_middle_dip" type="revolute">
    <origin rpy="0 0 0" xyz="-0.000000 0.000367 0.020997" />
    <parent link="R_middle_pip_link" />
    <child link="R_middle_dip_link" />
    <axis xyz="1 0 0" />
    <limit effort="5" lower="-0.30" upper="1.90" velocity="5" />
    <dynamics damping="0.1" friction="0.0" />
  </joint>
  <!-- Right index — 3 phalanges (r=6mm) -->
  <link name="R_index_mcp_link">
    <inertial>
      <origin rpy="0 0 0" xyz="0 0 0" />
      <mass value="0.008" />
      <inertia ixx="1e-6" ixy="0" ixz="0" iyy="1e-6" iyz="0" izz="1e-6" />
    </inertial>
    <visual>
      <origin rpy="0 0 0" xyz="-0.078728 0.072208 0.042189" />
      <geometry>
        <mesh filename="file:///home/me/clean_ws/src/XP_robot/meshes/R_index_mcp_link.stl"
          scale="0.001 0.001 0.001" />
      </geometry>
      <material name="silver" />
    </visual>
    <collision>
      <origin rpy="0 0 0" xyz="0 0 -0.014" />
      <geometry>
        <cylinder length="0.028" radius="0.006" />
      </geometry>
    </collision>
  </link>
  <joint name="R_index_mcp" type="revolute">
    <origin rpy="-3.124129 -0.034832 -3.137014" xyz="0.026448 -0.000670 0.140799" />
    <parent link="R_palm" />
    <child link="R_index_mcp_link" />
    <axis xyz="-1 0 0" />
    <limit effort="5" lower="-0.60" upper="1.57" velocity="5" />
    <dynamics damping="0.1" friction="0.0" />
  </joint>
  <link name="R_index_pip_link">
    <inertial>
      <origin rpy="0 0 0" xyz="0 0 0" />
      <mass value="0.006" />
      <inertia ixx="1e-6" ixy="0" ixz="0" iyy="1e-6" iyz="0" izz="1e-6" />
    </inertial>
    <visual>
      <origin rpy="0 0 0" xyz="-0.077775 0.066971 0.065147" />
      <geometry>
        <mesh filename="file:///home/me/clean_ws/src/XP_robot/meshes/R_index_pip_link.stl"
          scale="0.001 0.001 0.001" />
      </geometry>
      <material name="silver" />
    </visual>
    <collision>
      <origin rpy="0 0 0" xyz="0 0 -0.011" />
      <geometry>
        <cylinder length="0.021" radius="0.006" />
      </geometry>
    </collision>
  </link>
  <joint name="R_index_pip" type="revolute">
    <origin rpy="0 0 0" xyz="-0.000002 0.000005 -0.027920" />
    <parent link="R_index_mcp_link" />
    <child link="R_index_pip_link" />
    <axis xyz="-1 0 0" />
    <limit effort="5" lower="-0.20" upper="1.57" velocity="5" />
    <dynamics damping="0.1" friction="0.0" />
  </joint>
  <link name="R_index_dip_link">
    <inertial>
      <origin rpy="0 0 0" xyz="0 0 0" />
      <mass value="0.005" />
      <inertia ixx="1e-6" ixy="0" ixz="0" iyy="1e-6" iyz="0" izz="1e-6" />
    </inertial>
    <visual>
      <origin rpy="0 0 0" xyz="-0.076912 0.061698 0.090830" />
      <geometry>
        <mesh filename="file:///home/me/clean_ws/src/XP_robot/meshes/R_index_dip_link.stl"
          scale="0.001 0.001 0.001" />
      </geometry>
      <material name="silver" />
    </visual>
    <collision>
      <origin rpy="0 0 0" xyz="0 0 -0.009" />
      <geometry>
        <cylinder length="0.016" radius="0.005" />
      </geometry>
    </collision>
  </link>
  <joint name="R_index_dip" type="revolute">
    <origin rpy="0 0 0" xyz="-0.000001 0.000367 -0.020997" />
    <parent link="R_index_pip_link" />
    <child link="R_index_dip_link" />
    <axis xyz="-1 0 0" />
    <limit effort="5" lower="-0.30" upper="1.90" velocity="5" />
    <dynamics damping="0.1" friction="0.0" />
  </joint>
  <!-- ══════════════════════════════════════════════════════════════════════════
         LEFT HAND
         All collision geometries are primitive shapes (box / cylinder / sphere).
         Visual meshes are unchanged.
    ══════════════════════════════════════════════════════════════════════════ -->
  <!-- Palm: flat box -->
  <link name="L_palm">
    <inertial>
      <origin rpy="0 0 0" xyz="0 0 0" />
      <mass value="0.5" />
      <inertia ixx="2e-4" ixy="0" ixz="0" iyy="2e-4" iyz="0" izz="1e-4" />
    </inertial>
    <visual>
      <origin rpy="0 0 0" xyz="0 0 0" />
      <geometry>
        <mesh filename="file:///home/me/clean_ws/src/XP_robot/meshes/L_palm.stl"
          scale="0.001 0.001 0.001" />
      </geometry>
      <material name="silver" />
    </visual>
    <collision>
      <origin rpy="0 0 0" xyz="0.0 0.0 -0.09" />
      <geometry>
        <box size="0.080 0.020 0.090" />
      </geometry>
    </collision>
  </link>
  <joint name="hand_roll_l" type="revolute">
    <origin rpy="0 0 0" xyz="0.003609 -0.034524 -0.153085" />
    <parent link="forearm_l" />
    <child link="L_palm" />
    <axis xyz="0 0 1" />
    <limit effort="10" lower="-3.1416" upper="3.1416" velocity="5" />
    <dynamics damping="0.5" friction="0.1" />
  </joint>
  <!-- Left thumb — 4 phalanges (r=8mm) -->
  <link name="L_thumb_yaw_link">
    <inertial>
      <origin rpy="0 0 0" xyz="0 0 0" />
      <mass value="0.010" />
      <inertia ixx="1e-6" ixy="0" ixz="0" iyy="1e-6" iyz="0" izz="1e-6" />
    </inertial>
    <visual>
      <origin rpy="0 0 0" xyz="-0.023000 0.011000 0.055250" />
      <geometry>
        <mesh filename="file:///home/me/clean_ws/src/XP_robot/meshes/L_thumb_yaw_link.stl"
          scale="0.001 0.001 0.001" />
      </geometry>
      <material name="silver" />
    </visual>
    <collision>
      <origin rpy="0 0 0" xyz="0 0 -0.013" />
      <geometry>
        <cylinder length="0.026" radius="0.008" />
      </geometry>
    </collision>
  </link>
  <joint name="L_thumb_yaw" type="revolute">
    <origin rpy="0 0 0" xyz="0.023000 -0.011000 -0.055250" />
    <parent link="L_palm" />
    <child link="L_thumb_yaw_link" />
    <axis xyz="0 0 1" />
    <limit effort="5" lower="-0.75" upper="0.60" velocity="5" />
    <dynamics damping="0.1" friction="0.0" />
  </joint>
  <link name="L_thumb_cmc_link">
    <inertial>
      <origin rpy="0 0 0" xyz="0 0 0" />
      <mass value="0.008" />
      <inertia ixx="1e-6" ixy="0" ixz="0" iyy="1e-6" iyz="0" izz="1e-6" />
    </inertial>
    <visual>
      <origin rpy="0 0 0" xyz="-0.027750 0.023000 0.062080" />
      <geometry>
        <mesh filename="file:///home/me/clean_ws/src/XP_robot/meshes/L_thumb_cmc_link.stl"
          scale="0.001 0.001 0.001" />
      </geometry>
      <material name="silver" />
    </visual>
    <collision>
      <origin rpy="1.5708 0 0" xyz="0 -0.031 0" />
      <geometry>
        <cylinder length="0.030" radius="0.008" />
      </geometry>
    </collision>
  </link>
  <joint name="L_thumb_cmc" type="revolute">
    <origin rpy="0 0 0" xyz="0.004750 -0.012000 -0.006830" />
    <parent link="L_thumb_yaw_link" />
    <child link="L_thumb_cmc_link" />
    <axis xyz="1 0 0" />
    <limit effort="5" lower="-0.60" upper="0.70" velocity="5" />
    <dynamics damping="0.1" friction="0.0" />
  </joint>
  <link name="L_thumb_mcp_link">
    <inertial>
      <origin rpy="0 0 0" xyz="0 0 0" />
      <mass value="0.007" />
      <inertia ixx="1e-6" ixy="0" ixz="0" iyy="1e-6" iyz="0" izz="1e-6" />
    </inertial>
    <visual>
      <origin rpy="0 0 0" xyz="-0.027700 0.085000 0.070080" />
      <geometry>
        <mesh filename="file:///home/me/clean_ws/src/XP_robot/meshes/L_thumb_mcp_link.stl"
          scale="0.001 0.001 0.001" />
      </geometry>
      <material name="silver" />
    </visual>
    <collision>
      <origin rpy="1.5708 0 0" xyz="0 -0.010 0.009" />
      <geometry>
        <cylinder length="0.019" radius="0.008" />
      </geometry>
    </collision>
  </link>
  <joint name="L_thumb_mcp" type="revolute">
    <origin rpy="0 0 0" xyz="-0.000050 -0.062000 -0.008000" />
    <parent link="L_thumb_cmc_link" />
    <child link="L_thumb_mcp_link" />
    <axis xyz="1 0 0" />
    <limit effort="5" lower="0.00" upper="1.57" velocity="5" />
    <dynamics damping="0.1" friction="0.0" />
  </joint>
  <link name="L_thumb_ip_link">
    <inertial>
      <origin rpy="0 0 0" xyz="0 0 0" />
      <mass value="0.006" />
      <inertia ixx="1e-6" ixy="0" ixz="0" iyy="1e-6" iyz="0" izz="1e-6" />
    </inertial>
    <visual>
      <origin rpy="0 0 0" xyz="-0.027700 0.104000 0.070080" />
      <geometry>
        <mesh filename="file:///home/me/clean_ws/src/XP_robot/meshes/L_thumb_ip_link.stl"
          scale="0.001 0.001 0.001" />
      </geometry>
      <material name="silver" />
    </visual>
    <collision>
      <origin rpy="1.5708 0 0" xyz="0 -0.010 0.009" />
      <geometry>
        <cylinder length="0.018" radius="0.007" />
      </geometry>
    </collision>
  </link>
  <joint name="L_thumb_ip" type="revolute">
    <origin rpy="0 0 0" xyz="0.000000 -0.019000 -0.000000" />
    <parent link="L_thumb_mcp_link" />
    <child link="L_thumb_ip_link" />
    <axis xyz="1 0 0" />
    <limit effort="5" lower="-0.13" upper="0.95" velocity="5" />
    <dynamics damping="0.1" friction="0.0" />
  </joint>
  <!-- Left index — 3 phalanges (r=6mm) -->
  <link name="L_index_mcp_link">
    <inertial>
      <origin rpy="0 0 0" xyz="0 0 0" />
      <mass value="0.008" />
      <inertia ixx="1e-6" ixy="0" ixz="0" iyy="1e-6" iyz="0" izz="1e-6" />
    </inertial>
    <visual>
      <origin rpy="0 0 0" xyz="-0.034443 0.000670 0.140520" />
      <geometry>
        <mesh filename="file:///home/me/clean_ws/src/XP_robot/meshes/L_index_mcp_link.stl"
          scale="0.001 0.001 0.001" />
      </geometry>
      <material name="silver" />
    </visual>
    <collision>
      <origin rpy="0 0 0" xyz="0 0 -0.014" />
      <geometry>
        <cylinder length="0.028" radius="0.006" />
      </geometry>
    </collision>
  </link>
  <joint name="L_index_mcp" type="revolute">
    <origin rpy="0 0 0" xyz="0.034443 -0.000670 -0.140520" />
    <parent link="L_palm" />
    <child link="L_index_mcp_link" />
    <axis xyz="-1 0 0" />
    <limit effort="5" lower="-0.50" upper="1.57" velocity="5" />
    <dynamics damping="0.1" friction="0.0" />
  </joint>
  <link name="L_index_pip_link">
    <inertial>
      <origin rpy="0 0 0" xyz="0 0 0" />
      <mass value="0.006" />
      <inertia ixx="1e-6" ixy="0" ixz="0" iyy="1e-6" iyz="0" izz="1e-6" />
    </inertial>
    <visual>
      <origin rpy="0 0 0" xyz="-0.027422 0.001152 0.168698" />
      <geometry>
        <mesh filename="file:///home/me/clean_ws/src/XP_robot/meshes/L_index_pip_link.stl"
          scale="0.001 0.001 0.001" />
      </geometry>
      <material name="silver" />
    </visual>
    <collision>
      <origin rpy="0 0 0" xyz="0.007 0 -0.011" />
      <geometry>
        <cylinder length="0.021" radius="0.006" />
      </geometry>
    </collision>
  </link>
  <joint name="L_index_pip" type="revolute">
    <origin rpy="0 0 0" xyz="-0.007021 -0.000482 -0.028178" />
    <parent link="L_index_mcp_link" />
    <child link="L_index_pip_link" />
    <axis xyz="-1 0 0" />
    <limit effort="5" lower="-0.20" upper="1.57" velocity="5" />
    <dynamics damping="0.1" friction="0.0" />
  </joint>
  <link name="L_index_dip_link">
    <inertial>
      <origin rpy="0 0 0" xyz="0 0 0" />
      <mass value="0.005" />
      <inertia ixx="1e-6" ixy="0" ixz="0" iyy="1e-6" iyz="0" izz="1e-6" />
    </inertial>
    <visual>
      <origin rpy="0 0 0" xyz="-0.036151 0.001152 0.189407" />
      <geometry>
        <mesh filename="file:///home/me/clean_ws/src/XP_robot/meshes/L_index_dip_link.stl"
          scale="0.001 0.001 0.001" />
      </geometry>
      <material name="silver" />
    </visual>
    <collision>
      <origin rpy="0 0 0" xyz="0.0 0 -0.009" />
      <geometry>
        <cylinder length="0.016" radius="0.005" />
      </geometry>
    </collision>
  </link>
  <joint name="L_index_dip" type="revolute">
    <origin rpy="0 0 0" xyz="0.008728 0.000000 -0.020709" />
    <parent link="L_index_pip_link" />
    <child link="L_index_dip_link" />
    <axis xyz="-1 0 0" />
    <limit effort="5" lower="-0.30" upper="1.90" velocity="5" />
    <dynamics damping="0.1" friction="0.0" />
  </joint>
  <!-- Left middle — 3 phalanges (r=6mm) -->
  <link name="L_middle_mcp_link">
    <inertial>
      <origin rpy="0 0 0" xyz="0 0 0" />
      <mass value="0.008" />
      <inertia ixx="1e-6" ixy="0" ixz="0" iyy="1e-6" iyz="0" izz="1e-6" />
    </inertial>
    <visual>
      <origin rpy="0 0 0" xyz="-0.014120 0.000670 0.141014" />
      <geometry>
        <mesh filename="file:///home/me/clean_ws/src/XP_robot/meshes/L_middle_mcp_link.stl"
          scale="0.001 0.001 0.001" />
      </geometry>
      <material name="silver" />
    </visual>
    <collision>
      <origin rpy="0 0 0" xyz="0 0 -0.014" />
      <geometry>
        <cylinder length="0.028" radius="0.006" />
      </geometry>
    </collision>
  </link>
  <joint name="L_middle_mcp" type="revolute">
    <origin rpy="0 0 0" xyz="0.014120 -0.000670 -0.141014" />
    <parent link="L_palm" />
    <child link="L_middle_mcp_link" />
    <axis xyz="-1 0 0" />
    <limit effort="5" lower="-0.50" upper="1.70" velocity="5" />
    <dynamics damping="0.1" friction="0.0" />
  </joint>
  <link name="L_middle_pip_link">
    <inertial>
      <origin rpy="0 0 0" xyz="0 0 0" />
      <mass value="0.006" />
      <inertia ixx="1e-6" ixy="0" ixz="0" iyy="1e-6" iyz="0" izz="1e-6" />
    </inertial>
    <visual>
      <origin rpy="0 0 0" xyz="-0.006120 0.000665 0.168934" />
      <geometry>
        <mesh filename="file:///home/me/clean_ws/src/XP_robot/meshes/L_middle_pip_link.stl"
          scale="0.001 0.001 0.001" />
      </geometry>
      <material name="silver" />
    </visual>
    <collision>
      <origin rpy="0 0 0" xyz="0.007 0 -0.011" />
      <geometry>
        <cylinder length="0.021" radius="0.006" />
      </geometry>
    </collision>
  </link>
  <joint name="L_middle_pip" type="revolute">
    <origin rpy="0 0 0" xyz="-0.008000 0.000005 -0.027920" />
    <parent link="L_middle_mcp_link" />
    <child link="L_middle_pip_link" />
    <axis xyz="-1 0 0" />
    <limit effort="5" lower="-0.20" upper="1.57" velocity="5" />
    <dynamics damping="0.1" friction="0.0" />
  </joint>
  <link name="L_middle_dip_link">
    <inertial>
      <origin rpy="0 0 0" xyz="0 0 0" />
      <mass value="0.005" />
      <inertia ixx="1e-6" ixy="0" ixz="0" iyy="1e-6" iyz="0" izz="1e-6" />
    </inertial>
    <visual>
      <origin rpy="0 0 0" xyz="-0.014120 0.000298 0.189931" />
      <geometry>
        <mesh filename="file:///home/me/clean_ws/src/XP_robot/meshes/L_middle_dip_link.stl"
          scale="0.001 0.001 0.001" />
      </geometry>
      <material name="silver" />
    </visual>
    <collision>
      <origin rpy="0 0 0" xyz="0 0 -0.009" />
      <geometry>
        <cylinder length="0.016" radius="0.005" />
      </geometry>
    </collision>
  </link>
  <joint name="L_middle_dip" type="revolute">
    <origin rpy="0 0 0" xyz="0.008000 0.000367 -0.020997" />
    <parent link="L_middle_pip_link" />
    <child link="L_middle_dip_link" />
    <axis xyz="-1 0 0" />
    <limit effort="5" lower="-0.30" upper="1.90" velocity="5" />
    <dynamics damping="0.1" friction="0.0" />
  </joint>
  <!-- Left ring — 3 phalanges (r=6mm) -->
  <link name="L_ring_mcp_link">
    <inertial>
      <origin rpy="0 0 0" xyz="0 0 0" />
      <mass value="0.008" />
      <inertia ixx="1e-6" ixy="0" ixz="0" iyy="1e-6" iyz="0" izz="1e-6" />
    </inertial>
    <visual>
      <origin rpy="0 0 0" xyz="0.006370 0.000670 0.140687" />
      <geometry>
        <mesh filename="file:///home/me/clean_ws/src/XP_robot/meshes/L_ring_mcp_link.stl"
          scale="0.001 0.001 0.001" />
      </geometry>
      <material name="silver" />
    </visual>
    <collision>
      <origin rpy="0 0 0" xyz="0 0 -0.014" />
      <geometry>
        <cylinder length="0.028" radius="0.006" />
      </geometry>
    </collision>
  </link>
  <joint name="L_ring_mcp" type="revolute">
    <origin rpy="0 0 0" xyz="-0.006370 -0.000670 -0.140687" />
    <parent link="L_palm" />
    <child link="L_ring_mcp_link" />
    <axis xyz="-1 0 0" />
    <limit effort="5" lower="-0.50" upper="1.70" velocity="5" />
    <dynamics damping="0.1" friction="0.0" />
  </joint>
  <link name="L_ring_pip_link">
    <inertial>
      <origin rpy="0 0 0" xyz="0 0 0" />
      <mass value="0.006" />
      <inertia ixx="1e-6" ixy="0" ixz="0" iyy="1e-6" iyz="0" izz="1e-6" />
    </inertial>
    <visual>
      <origin rpy="0 0 0" xyz="0.015820 0.001152 0.168146" />
      <geometry>
        <mesh filename="file:///home/me/clean_ws/src/XP_robot/meshes/L_ring_pip_link.stl"
          scale="0.001 0.001 0.001" />
      </geometry>
      <material name="silver" />
    </visual>
    <collision>
      <origin rpy="0 0 0" xyz="0.008 0 -0.011" />
      <geometry>
        <cylinder length="0.021" radius="0.006" />
      </geometry>
    </collision>
  </link>
  <joint name="L_ring_pip" type="revolute">
    <origin rpy="0 0 0" xyz="-0.009450 -0.000482 -0.027459" />
    <parent link="L_ring_mcp_link" />
    <child link="L_ring_pip_link" />
    <axis xyz="-1 0 0" />
    <limit effort="5" lower="-0.20" upper="1.57" velocity="5" />
    <dynamics damping="0.1" friction="0.0" />
  </joint>
  <link name="L_ring_dip_link">
    <inertial>
      <origin rpy="0 0 0" xyz="0 0 0" />
      <mass value="0.005" />
      <inertia ixx="1e-6" ixy="0" ixz="0" iyy="1e-6" iyz="0" izz="1e-6" />
    </inertial>
    <visual>
      <origin rpy="0 0 0" xyz="0.016919 0.001152 0.189117" />
      <geometry>
        <mesh filename="file:///home/me/clean_ws/src/XP_robot/meshes/L_ring_dip_link.stl"
          scale="0.001 0.001 0.001" />
      </geometry>
      <material name="silver" />
    </visual>
    <collision>
      <origin rpy="0 0 0" xyz="0.008 0 -0.009" />
      <geometry>
        <cylinder length="0.016" radius="0.005" />
      </geometry>
    </collision>
  </link>
  <joint name="L_ring_dip" type="revolute">
    <origin rpy="0 0 0" xyz="-0.001099 -0.000000 -0.020971" />
    <parent link="L_ring_pip_link" />
    <child link="L_ring_dip_link" />
    <axis xyz="-1 0 0" />
    <limit effort="5" lower="-0.30" upper="1.90" velocity="5" />
    <dynamics damping="0.1" friction="0.0" />
  </joint>
  <!-- Left pinky — 3 phalanges (r=6mm) -->
  <link name="L_pinky_mcp_link">
    <inertial>
      <origin rpy="0 0 0" xyz="0 0 0" />
      <mass value="0.008" />
      <inertia ixx="1e-6" ixy="0" ixz="0" iyy="1e-6" iyz="0" izz="1e-6" />
    </inertial>
    <visual>
      <origin rpy="0 0 0" xyz="0.027098 0.000670 0.135175" />
      <geometry>
        <mesh filename="file:///home/me/clean_ws/src/XP_robot/meshes/L_pinky_mcp_link.stl"
          scale="0.001 0.001 0.001" />
      </geometry>
      <material name="silver" />
    </visual>
    <collision>
      <origin rpy="0 0 0" xyz="0 0 -0.02" />
      <geometry>
        <cylinder length="0.026" radius="0.006" />
      </geometry>
    </collision>
  </link>
  <joint name="L_pinky_mcp" type="revolute">
    <origin rpy="0 0 0" xyz="-0.027098 -0.000670 -0.135175" />
    <parent link="L_palm" />
    <child link="L_pinky_mcp_link" />
    <axis xyz="-1 0 0" />
    <limit effort="5" lower="-0.50" upper="1.57" velocity="5" />
    <dynamics damping="0.1" friction="0.0" />
  </joint>
  <link name="L_pinky_pip_link">
    <inertial>
      <origin rpy="0 0 0" xyz="0 0 0" />
      <mass value="0.006" />
      <inertia ixx="1e-6" ixy="0" ixz="0" iyy="1e-6" iyz="0" izz="1e-6" />
    </inertial>
    <visual>
      <origin rpy="0 0 0" xyz="0.037973 0.000665 0.162106" />
      <geometry>
        <mesh filename="file:///home/me/clean_ws/src/XP_robot/meshes/L_pinky_pip_link.stl"
          scale="0.001 0.001 0.001" />
      </geometry>
      <material name="silver" />
    </visual>
    <collision>
      <origin rpy="0 0 0" xyz="0.008 0 -0.017" />
      <geometry>
        <cylinder length="0.021" radius="0.006" />
      </geometry>
    </collision>
  </link>
  <joint name="L_pinky_pip" type="revolute">
    <origin rpy="0 0 0" xyz="-0.010875 0.000005 -0.026932" />
    <parent link="L_pinky_mcp_link" />
    <child link="L_pinky_pip_link" />
    <axis xyz="-1 0 0" />
    <limit effort="5" lower="-0.20" upper="1.57" velocity="5" />
    <dynamics damping="0.1" friction="0.0" />
  </joint>
  <link name="L_pinky_dip_link">
    <inertial>
      <origin rpy="0 0 0" xyz="0 0 0" />
      <mass value="0.005" />
      <inertia ixx="1e-6" ixy="0" ixz="0" iyy="1e-6" iyz="0" izz="1e-6" />
    </inertial>
    <visual>
      <origin rpy="0 0 0" xyz="0.032212 0.000298 0.183824" />
      <geometry>
        <mesh filename="file:///home/me/clean_ws/src/XP_robot/meshes/L_pinky_dip_link.stl"
          scale="0.001 0.001 0.001" />
      </geometry>
      <material name="silver" />
    </visual>
    <collision>
      <origin rpy="0 0 0" xyz="0.002 0 -0.015" />
      <geometry>
        <cylinder length="0.016" radius="0.005" />
      </geometry>
    </collision>
  </link>
  <joint name="L_pinky_dip" type="revolute">
    <origin rpy="0 0 0" xyz="0.005761 0.000367 -0.021718" />
    <parent link="L_pinky_pip_link" />
    <child link="L_pinky_dip_link" />
    <axis xyz="-1 0 0" />
    <limit effort="5" lower="-0.30" upper="1.80" velocity="5" />
    <dynamics damping="0.1" friction="0.0" />
  </joint>
  <ros2_control name="FullBodyMujocoSystem" type="system">
    <hardware>
      <plugin>mujoco_ros2_control/MujocoSystem</plugin>
    </hardware>
    <joint name="hip_pitch_r">
      <command_interface name="position">
        <param name="min">-3.1416</param>
        <param name="max">3.1416</param>
      </command_interface>
      <state_interface name="position">
        <param name="initial_value">0.0</param>
      </state_interface>
      <state_interface name="velocity">
        <param name="initial_value">0.0</param>
      </state_interface>
    </joint>
    <joint name="hip_roll_r">
      <command_interface name="position">
        <param name="min">-2.35</param>
        <param name="max">0.292</param>
      </command_interface>
      <state_interface name="position">
        <param name="initial_value">0.0</param>
      </state_interface>
      <state_interface name="velocity">
        <param name="initial_value">0.0</param>
      </state_interface>
    </joint>
    <joint name="thigh_yaw_r">
      <command_interface name="position">
        <param name="min">-3.1416</param>
        <param name="max">3.1416</param>
      </command_interface>
      <state_interface name="position">
        <param name="initial_value">0.0</param>
      </state_interface>
      <state_interface name="velocity">
        <param name="initial_value">0.0</param>
      </state_interface>
    </joint>
    <joint name="knee_pitch_r">
      <command_interface name="position">
        <param name="min">-1.5708</param>
        <param name="max">0.0</param>
      </command_interface>
      <state_interface name="position">
        <param name="initial_value">0.0</param>
      </state_interface>
      <state_interface name="velocity">
        <param name="initial_value">0.0</param>
      </state_interface>
    </joint>
    <joint name="ankle_pitch_r">
      <command_interface name="position">
        <param name="min">-0.6981</param>
        <param name="max">0.6981</param>
      </command_interface>
      <state_interface name="position">
        <param name="initial_value">0.0</param>
      </state_interface>
      <state_interface name="velocity">
        <param name="initial_value">0.0</param>
      </state_interface>
    </joint>
    <joint name="ankle_roll_r">
      <command_interface name="position">
        <param name="min">-0.3491</param>
        <param name="max">0.3491</param>
      </command_interface>
      <state_interface name="position">
        <param name="initial_value">0.0</param>
      </state_interface>
      <state_interface name="velocity">
        <param name="initial_value">0.0</param>
      </state_interface>
    </joint>
    <joint name="hip_pitch_l">
      <command_interface name="position">
        <param name="min">-3.1416</param>
        <param name="max">3.1416</param>
      </command_interface>
      <state_interface name="position">
        <param name="initial_value">0.0</param>
      </state_interface>
      <state_interface name="velocity">
        <param name="initial_value">0.0</param>
      </state_interface>
    </joint>
    <joint name="hip_roll_l">
      <command_interface name="position">
        <param name="min">-0.292</param>
        <param name="max">2.35</param>
      </command_interface>
      <state_interface name="position">
        <param name="initial_value">0.0</param>
      </state_interface>
      <state_interface name="velocity">
        <param name="initial_value">0.0</param>
      </state_interface>
    </joint>
    <joint name="thigh_yaw_l">
      <command_interface name="position">
        <param name="min">-3.1416</param>
        <param name="max">3.1416</param>
      </command_interface>
      <state_interface name="position">
        <param name="initial_value">0.0</param>
      </state_interface>
      <state_interface name="velocity">
        <param name="initial_value">0.0</param>
      </state_interface>
    </joint>
    <joint name="knee_pitch_l">
      <command_interface name="position">
        <param name="min">-1.5708</param>
        <param name="max">0.0</param>
      </command_interface>
      <state_interface name="position">
        <param name="initial_value">0.0</param>
      </state_interface>
      <state_interface name="velocity">
        <param name="initial_value">0.0</param>
      </state_interface>
    </joint>
    <joint name="ankle_pitch_l">
      <command_interface name="position">
        <param name="min">-0.6981</param>
        <param name="max">0.6981</param>
      </command_interface>
      <state_interface name="position">
        <param name="initial_value">0.0</param>
      </state_interface>
      <state_interface name="velocity">
        <param name="initial_value">0.0</param>
      </state_interface>
    </joint>
    <joint name="ankle_roll_l">
      <command_interface name="position">
        <param name="min">-0.3491</param>
        <param name="max">0.3491</param>
      </command_interface>
      <state_interface name="position">
        <param name="initial_value">0.0</param>
      </state_interface>
      <state_interface name="velocity">
        <param name="initial_value">0.0</param>
      </state_interface>
    </joint>
    <joint name="torso_yaw">
      <command_interface name="position">
        <param name="min">-3.1416</param>
        <param name="max">3.1416</param>
      </command_interface>
      <state_interface name="position">
        <param name="initial_value">0.0</param>
      </state_interface>
      <state_interface name="velocity">
        <param name="initial_value">0.0</param>
      </state_interface>
    </joint>
    <joint name="shoulder_pitch_r">
      <command_interface name="position">
        <param name="min">-3.1416</param>
        <param name="max">3.1416</param>
      </command_interface>
      <state_interface name="position">
        <param name="initial_value">0.0</param>
      </state_interface>
      <state_interface name="velocity">
        <param name="initial_value">0.0</param>
      </state_interface>
    </joint>
    <joint name="shoulder_roll_r">
      <command_interface name="position">
        <param name="min">-0.0873</param>
        <param name="max">3.3161</param>
      </command_interface>
      <state_interface name="position">
        <param name="initial_value">0.0</param>
      </state_interface>
      <state_interface name="velocity">
        <param name="initial_value">0.0</param>
      </state_interface>
    </joint>
    <joint name="elbow_yaw_r">
      <command_interface name="position">
        <param name="min">-3.1416</param>
        <param name="max">3.1416</param>
      </command_interface>
      <state_interface name="position">
        <param name="initial_value">0.0</param>
      </state_interface>
      <state_interface name="velocity">
        <param name="initial_value">0.0</param>
      </state_interface>
    </joint>
    <joint name="elbow_pitch_r">
      <command_interface name="position">
        <param name="min">-2.5307</param>
        <param name="max">0.0</param>
      </command_interface>
      <state_interface name="position">
        <param name="initial_value">0.0</param>
      </state_interface>
      <state_interface name="velocity">
        <param name="initial_value">0.0</param>
      </state_interface>
    </joint>
    <joint name="shoulder_pitch_l">
      <command_interface name="position">
        <param name="min">-3.1416</param>
        <param name="max">3.1416</param>
      </command_interface>
      <state_interface name="position">
        <param name="initial_value">0.0</param>
      </state_interface>
      <state_interface name="velocity">
        <param name="initial_value">0.0</param>
      </state_interface>
    </joint>
    <joint name="shoulder_roll_l">
      <command_interface name="position">
        <param name="min">-3.3161</param>
        <param name="max">0.0873</param>
      </command_interface>
      <state_interface name="position">
        <param name="initial_value">0.0</param>
      </state_interface>
      <state_interface name="velocity">
        <param name="initial_value">0.0</param>
      </state_interface>
    </joint>
    <joint name="elbow_yaw_l">
      <command_interface name="position">
        <param name="min">-3.1416</param>
        <param name="max">3.1416</param>
      </command_interface>
      <state_interface name="position">
        <param name="initial_value">0.0</param>
      </state_interface>
      <state_interface name="velocity">
        <param name="initial_value">0.0</param>
      </state_interface>
    </joint>
    <joint name="elbow_pitch_l">
      <command_interface name="position">
        <param name="min">-2.5307</param>
        <param name="max">0.0</param>
      </command_interface>
      <state_interface name="position">
        <param name="initial_value">0.0</param>
      </state_interface>
      <state_interface name="velocity">
        <param name="initial_value">0.0</param>
      </state_interface>
    </joint>
    <joint name="hand_roll_r">
      <command_interface name="position">
        <param name="min">-3.1416</param>
        <param name="max">3.1416</param>
      </command_interface>
      <state_interface name="position">
        <param name="initial_value">0.0</param>
      </state_interface>
      <state_interface name="velocity">
        <param name="initial_value">0.0</param>
      </state_interface>
    </joint>
    <joint name="R_thumb_yaw">
      <command_interface name="position">
        <param name="min">-0.6</param>
        <param name="max">0.75</param>
      </command_interface>
      <state_interface name="position">
        <param name="initial_value">0.0</param>
      </state_interface>
      <state_interface name="velocity">
        <param name="initial_value">0.0</param>
      </state_interface>
    </joint>
    <joint name="R_thumb_cmc">
      <command_interface name="position">
        <param name="min">-0.6</param>
        <param name="max">0.7</param>
      </command_interface>
      <state_interface name="position">
        <param name="initial_value">0.0</param>
      </state_interface>
      <state_interface name="velocity">
        <param name="initial_value">0.0</param>
      </state_interface>
    </joint>
    <joint name="R_thumb_mcp">
      <command_interface name="position">
        <param name="min">-1.57</param>
        <param name="max">0.0</param>
      </command_interface>
      <state_interface name="position">
        <param name="initial_value">0.0</param>
      </state_interface>
      <state_interface name="velocity">
        <param name="initial_value">0.0</param>
      </state_interface>
    </joint>
    <joint name="R_thumb_ip">
      <command_interface name="position">
        <param name="min">-0.95</param>
        <param name="max">0.13</param>
      </command_interface>
      <state_interface name="position">
        <param name="initial_value">0.0</param>
      </state_interface>
      <state_interface name="velocity">
        <param name="initial_value">0.0</param>
      </state_interface>
    </joint>
    <joint name="R_pinky_mcp">
      <command_interface name="position">
        <param name="min">-0.5</param>
        <param name="max">1.57</param>
      </command_interface>
      <state_interface name="position">
        <param name="initial_value">0.0</param>
      </state_interface>
      <state_interface name="velocity">
        <param name="initial_value">0.0</param>
      </state_interface>
    </joint>
    <joint name="R_pinky_pip">
      <command_interface name="position">
        <param name="min">-0.13</param>
        <param name="max">1.57</param>
      </command_interface>
      <state_interface name="position">
        <param name="initial_value">0.0</param>
      </state_interface>
      <state_interface name="velocity">
        <param name="initial_value">0.0</param>
      </state_interface>
    </joint>
    <joint name="R_pinky_dip">
      <command_interface name="position">
        <param name="min">-0.3</param>
        <param name="max">1.8</param>
      </command_interface>
      <state_interface name="position">
        <param name="initial_value">0.0</param>
      </state_interface>
      <state_interface name="velocity">
        <param name="initial_value">0.0</param>
      </state_interface>
    </joint>
    <joint name="R_ring_mcp">
      <command_interface name="position">
        <param name="min">-0.5</param>
        <param name="max">1.7</param>
      </command_interface>
      <state_interface name="position">
        <param name="initial_value">0.0</param>
      </state_interface>
      <state_interface name="velocity">
        <param name="initial_value">0.0</param>
      </state_interface>
    </joint>
    <joint name="R_ring_pip">
      <command_interface name="position">
        <param name="min">-0.13</param>
        <param name="max">1.57</param>
      </command_interface>
      <state_interface name="position">
        <param name="initial_value">0.0</param>
      </state_interface>
      <state_interface name="velocity">
        <param name="initial_value">0.0</param>
      </state_interface>
    </joint>
    <joint name="R_ring_dip">
      <command_interface name="position">
        <param name="min">-0.3</param>
        <param name="max">1.9</param>
      </command_interface>
      <state_interface name="position">
        <param name="initial_value">0.0</param>
      </state_interface>
      <state_interface name="velocity">
        <param name="initial_value">0.0</param>
      </state_interface>
    </joint>
    <joint name="R_middle_mcp">
      <command_interface name="position">
        <param name="min">-0.5</param>
        <param name="max">1.7</param>
      </command_interface>
      <state_interface name="position">
        <param name="initial_value">0.0</param>
      </state_interface>
      <state_interface name="velocity">
        <param name="initial_value">0.0</param>
      </state_interface>
    </joint>
    <joint name="R_middle_pip">
      <command_interface name="position">
        <param name="min">-0.13</param>
        <param name="max">1.57</param>
      </command_interface>
      <state_interface name="position">
        <param name="initial_value">0.0</param>
      </state_interface>
      <state_interface name="velocity">
        <param name="initial_value">0.0</param>
      </state_interface>
    </joint>
    <joint name="R_middle_dip">
      <command_interface name="position">
        <param name="min">-0.3</param>
        <param name="max">1.9</param>
      </command_interface>
      <state_interface name="position">
        <param name="initial_value">0.0</param>
      </state_interface>
      <state_interface name="velocity">
        <param name="initial_value">0.0</param>
      </state_interface>
    </joint>
    <joint name="R_index_mcp">
      <command_interface name="position">
        <param name="min">-0.6</param>
        <param name="max">1.57</param>
      </command_interface>
      <state_interface name="position">
        <param name="initial_value">0.0</param>
      </state_interface>
      <state_interface name="velocity">
        <param name="initial_value">0.0</param>
      </state_interface>
    </joint>
    <joint name="R_index_pip">
      <command_interface name="position">
        <param name="min">-0.2</param>
        <param name="max">1.57</param>
      </command_interface>
      <state_interface name="position">
        <param name="initial_value">0.0</param>
      </state_interface>
      <state_interface name="velocity">
        <param name="initial_value">0.0</param>
      </state_interface>
    </joint>
    <joint name="R_index_dip">
      <command_interface name="position">
        <param name="min">-0.3</param>
        <param name="max">1.9</param>
      </command_interface>
      <state_interface name="position">
        <param name="initial_value">0.0</param>
      </state_interface>
      <state_interface name="velocity">
        <param name="initial_value">0.0</param>
      </state_interface>
    </joint>
    <joint name="hand_roll_l">
      <command_interface name="position">
        <param name="min">-3.14</param>
        <param name="max">3.14</param>
      </command_interface>
      <state_interface name="position">
        <param name="initial_value">0.0</param>
      </state_interface>
      <state_interface name="velocity">
        <param name="initial_value">0.0</param>
      </state_interface>
    </joint>
    <joint name="L_thumb_yaw">
      <command_interface name="position">
        <param name="min">-0.75</param>
        <param name="max">0.6</param>
      </command_interface>
      <state_interface name="position">
        <param name="initial_value">0.0</param>
      </state_interface>
      <state_interface name="velocity">
        <param name="initial_value">0.0</param>
      </state_interface>
    </joint>
    <joint name="L_thumb_cmc">
      <command_interface name="position">
        <param name="min">-0.6</param>
        <param name="max">0.7</param>
      </command_interface>
      <state_interface name="position">
        <param name="initial_value">0.0</param>
      </state_interface>
      <state_interface name="velocity">
        <param name="initial_value">0.0</param>
      </state_interface>
    </joint>
    <joint name="L_thumb_mcp">
      <command_interface name="position">
        <param name="min">0.0</param>
        <param name="max">1.57</param>
      </command_interface>
      <state_interface name="position">
        <param name="initial_value">0.0</param>
      </state_interface>
      <state_interface name="velocity">
        <param name="initial_value">0.0</param>
      </state_interface>
    </joint>
    <joint name="L_thumb_ip">
      <command_interface name="position">
        <param name="min">-0.13</param>
        <param name="max">0.95</param>
      </command_interface>
      <state_interface name="position">
        <param name="initial_value">0.0</param>
      </state_interface>
      <state_interface name="velocity">
        <param name="initial_value">0.0</param>
      </state_interface>
    </joint>
    <joint name="L_index_mcp">
      <command_interface name="position">
        <param name="min">-0.5</param>
        <param name="max">1.57</param>
      </command_interface>
      <state_interface name="position">
        <param name="initial_value">0.0</param>
      </state_interface>
      <state_interface name="velocity">
        <param name="initial_value">0.0</param>
      </state_interface>
    </joint>
    <joint name="L_index_pip">
      <command_interface name="position">
        <param name="min">-0.2</param>
        <param name="max">1.57</param>
      </command_interface>
      <state_interface name="position">
        <param name="initial_value">0.0</param>
      </state_interface>
      <state_interface name="velocity">
        <param name="initial_value">0.0</param>
      </state_interface>
    </joint>
    <joint name="L_index_dip">
      <command_interface name="position">
        <param name="min">-0.3</param>
        <param name="max">1.9</param>
      </command_interface>
      <state_interface name="position">
        <param name="initial_value">0.0</param>
      </state_interface>
      <state_interface name="velocity">
        <param name="initial_value">0.0</param>
      </state_interface>
    </joint>
    <joint name="L_middle_mcp">
      <command_interface name="position">
        <param name="min">-0.5</param>
        <param name="max">1.7</param>
      </command_interface>
      <state_interface name="position">
        <param name="initial_value">0.0</param>
      </state_interface>
      <state_interface name="velocity">
        <param name="initial_value">0.0</param>
      </state_interface>
    </joint>
    <joint name="L_middle_pip">
      <command_interface name="position">
        <param name="min">-0.2</param>
        <param name="max">1.57</param>
      </command_interface>
      <state_interface name="position">
        <param name="initial_value">0.0</param>
      </state_interface>
      <state_interface name="velocity">
        <param name="initial_value">0.0</param>
      </state_interface>
    </joint>
    <joint name="L_middle_dip">
      <command_interface name="position">
        <param name="min">-0.3</param>
        <param name="max">1.9</param>
      </command_interface>
      <state_interface name="position">
        <param name="initial_value">0.0</param>
      </state_interface>
      <state_interface name="velocity">
        <param name="initial_value">0.0</param>
      </state_interface>
    </joint>
    <joint name="L_ring_mcp">
      <command_interface name="position">
        <param name="min">-0.5</param>
        <param name="max">1.7</param>
      </command_interface>
      <state_interface name="position">
        <param name="initial_value">0.0</param>
      </state_interface>
      <state_interface name="velocity">
        <param name="initial_value">0.0</param>
      </state_interface>
    </joint>
    <joint name="L_ring_pip">
      <command_interface name="position">
        <param name="min">-0.2</param>
        <param name="max">1.57</param>
      </command_interface>
      <state_interface name="position">
        <param name="initial_value">0.0</param>
      </state_interface>
      <state_interface name="velocity">
        <param name="initial_value">0.0</param>
      </state_interface>
    </joint>
    <joint name="L_ring_dip">
      <command_interface name="position">
        <param name="min">-0.3</param>
        <param name="max">1.9</param>
      </command_interface>
      <state_interface name="position">
        <param name="initial_value">0.0</param>
      </state_interface>
      <state_interface name="velocity">
        <param name="initial_value">0.0</param>
      </state_interface>
    </joint>
    <joint name="L_pinky_mcp">
      <command_interface name="position">
        <param name="min">-0.5</param>
        <param name="max">1.57</param>
      </command_interface>
      <state_interface name="position">
        <param name="initial_value">0.0</param>
      </state_interface>
      <state_interface name="velocity">
        <param name="initial_value">0.0</param>
      </state_interface>
    </joint>
    <joint name="L_pinky_pip">
      <command_interface name="position">
        <param name="min">-0.2</param>
        <param name="max">1.57</param>
      </command_interface>
      <state_interface name="position">
        <param name="initial_value">0.0</param>
      </state_interface>
      <state_interface name="velocity">
        <param name="initial_value">0.0</param>
      </state_interface>
    </joint>
    <joint name="L_pinky_dip">
      <command_interface name="position">
        <param name="min">-0.3</param>
        <param name="max">1.8</param>
      </command_interface>
      <state_interface name="position">
        <param name="initial_value">0.0</param>
      </state_interface>
      <state_interface name="velocity">
        <param name="initial_value">0.0</param>
      </state_interface>
    </joint>
  </ros2_control>
</robot>